<?xml version="1.0"?>
<robot name="self_balancer" xmlns:xacro="http://www.ros.org/wiki/xacro">
  <xacro:property name="wheel_radius" value="0.035"/>
  <xacro:property name="wheel_base" value="0.14"/>

  <link name="base_link">
    <inertial>
      <mass value="2.0"/>
      <origin xyz="0 0 0" rpy="0 0 0"/>
      <inertia ixx="0.03" iyy="0.03" izz="0.03"/>
    </inertial>
    <visual>
      <geometry>
        <box size="0.25 0.15 0.05"/>
      </geometry>
      <material name="grey"/>
    </visual>
  </link>

  <link name="wheel_left"/>
  <link name="wheel_right"/>

  <joint name="wheel_left_joint" type="continuous">
    <parent link="base_link"/>
    <child link="wheel_left"/>
    <origin xyz="0 ${wheel_base/2} ${-wheel_radius}" rpy="0 0 0"/>
    <axis xyz="0 1 0"/>
  </joint>

  <joint name="wheel_right_joint" type="continuous">
    <parent link="base_link"/>
    <child link="wheel_right"/>
    <origin xyz="0 ${-wheel_base/2} ${-wheel_radius}" rpy="0 0 0"/>
    <axis xyz="0 1 0"/>
  </joint>

  <link name="imu_link"/>
  <joint name="imu_joint" type="fixed">
    <parent link="base_link"/>
    <child link="imu_link"/>
    <origin xyz="0 0 0.025" rpy="0 0 0"/>
  </joint>

  <gazebo reference="base_link">
    <material>Gazebo/Grey</material>
  </gazebo>
</robot>
